Workbook

Sheet Referência LC 214
A1: Referência da LC 214 por NCM e NBS — reduções e alíquota zero
A2: Como ler: o “Código” pode ser só o começo do NCM/NBS — a regra vale para todos os códigos que começam com ele, menos os da coluna “Exceções”. Um mesmo código pode aparecer em mais de uma linha: quem decide é a descrição do produto (coluna G) e, às vezes, o comprador (coluna L).
A3: NCM/NBS que não aparece aqui: alíquota cheia (cClassTrib 000001), salvo regimes específicos (combustíveis, financeiro, imóveis etc.). Medicamentos dependem também do registro na Anvisa (conferir).
A4: Fonte: @sinete/ibs-cbs-dados@2026.9.3 (dados 2026.09, licença Apache-2.0), extraído da Calculadora da Receita (módulo offline V0059) e do Informe Técnico 2025.002 v1.60. Material de estudo — confirmar na lei e nas tabelas oficiais vigentes.
A5: Tipo | B5: Código | C5: Abrange | D5: Exceções (não vale) | E5: Anexo | F5: Item | G5: Descrição do item no anexo | H5: Tratamento | I5: cClassTrib | J5: CST | K5: Redução | L5: Condição para valer | M5: Base legal | N5: Chave
A6: Produto | B6: 0102 | C6: Todos os NCM que começam com 0102 | E6: IX | F6: 15 | G6: Reprodutores de raça pura, inclusive matrizes de animais puros de origem com registro genealógico; em conformidade com as definições e demais requisitos da legislação específica | H6: Insumos agropecuários e aquícolas — redução de 60% | I6: 200038 | J6: 200 | K6: 0.6 | M6: Art. 138 | N6: P0102
A7: Produto | B7: 0103 | C7: Todos os NCM que começam com 0103 | E7: IX | F7: 15 | G7: Reprodutores de raça pura, inclusive matrizes de animais puros de origem com registro genealógico; em conformidade com as definições e demais requisitos da legislação específica | H7: Insumos agropecuários e aquícolas — redução de 60% | I7: 200038 | J7: 200 | K7: 0.6 | M7: Art. 138 | N7: P0103
A8: Produto | B8: 0104 | C8: Todos os NCM que começam com 0104 | E8: IX | F8: 15 | G8: Reprodutores de raça pura, inclusive matrizes de animais puros de origem com registro genealógico; em conformidade com as definições e demais requisitos da legislação específica | H8: Insumos agropecuários e aquícolas — redução de 60% | I8: 200038 | J8: 200 | K8: 0.6 | M8: Art. 138 | N8: P0104
A9: Produto | B9: 0105.1 | C9: Todos os NCM que começam com 0105.1 | E9: IX | F9: 13 | G9: Aves de um dia, exceto as ornamentais | H9: Insumos agropecuários e aquícolas — redução de 60% | I9: 200038 | J9: 200 | K9: 0.6 | M9: Art. 138 | N9: P01051
A10: Produto | B10: 0106.90.00 | C10: Só este NCM | E10: IX | F10: 17 | G10: Girinos e alevinos | H10: Insumos agropecuários e aquícolas — redução de 60% | I10: 200038 | J10: 200 | K10: 0.6 | M10: Art. 138 | N10: P01069000
A11: Produto | B11: 0201 | C11: Todos os NCM que começam com 0201 | E11: I | F11: 19 | G11: Carnes bovina, suína, ovina, caprina e de aves e produtos de origem animal (excetofoiesgras)dos seguintes códigos, subposições e posições da NCM/SH: a) 02.01, 02.02, 0206.10.00, 0206.2 e 0210.20.00; b) 02.03, 0206.30.00, 0206.4, 0209.10 e 0210.1; c) 02.04 e 0210.99.20, carne caprina classificada no código 0210.99.90 e miudezas comestíveis de ovinos e caprinos classificadas nos códigos 0206.80.00 e 0206.90.00; d) 02.07, 0209.90.00 e 0210.99.1, exceto os produtos dos códigos 0207.43.00 e 0207.53.00 | H11: Cesta Básica Nacional de Alimentos — alíquota zero | I11: 200003 | J11: 200 | K11: 1 | M11: Art. 125 | N11: P0201
A12: Produto | B12: 0202 | C12: Todos os NCM que começam com 0202 | E12: I | F12: 19 | G12: Carnes bovina, suína, ovina, caprina e de aves e produtos de origem animal (excetofoiesgras)dos seguintes códigos, subposições e posições da NCM/SH: a) 02.01, 02.02, 0206.10.00, 0206.2 e 0210.20.00; b) 02.03, 0206.30.00, 0206.4, 0209.10 e 0210.1; c) 02.04 e 0210.99.20, carne caprina classificada no código 0210.99.90 e miudezas comestíveis de ovinos e caprinos classificadas nos códigos 0206.80.00 e 0206.90.00; d) 02.07, 0209.90.00 e 0210.99.1, exceto os produtos dos códigos 0207.43.00 e 0207.53.00 | H12: Cesta Básica Nacional de Alimentos — alíquota zero | I12: 200003 | J12: 200 | K12: 1 | M12: Art. 125 | N12: P0202
A13: Produto | B13: 0203 | C13: Todos os NCM que começam com 0203 | E13: I | F13: 19 | G13: Carnes bovina, suína, ovina, caprina e de aves e produtos de origem animal (excetofoiesgras)dos seguintes códigos, subposições e posições da NCM/SH: a) 02.01, 02.02, 0206.10.00, 0206.2 e 0210.20.00; b) 02.03, 0206.30.00, 0206.4, 0209.10 e 0210.1; c) 02.04 e 0210.99.20, carne caprina classificada no código 0210.99.90 e miudezas comestíveis de ovinos e caprinos classificadas nos códigos 0206.80.00 e 0206.90.00; d) 02.07, 0209.90.00 e 0210.99.1, exceto os produtos dos códigos 0207.43.00 e 0207.53.00 | H13: Cesta Básica Nacional de Alimentos — alíquota zero | I13: 200003 | J13: 200 | K13: 1 | M13: Art. 125 | N13: P0203
A14: Produto | B14: 0204 | C14: Todos os NCM que começam com 0204 | E14: I | F14: 19 | G14: Carnes bovina, suína, ovina, caprina e de aves e produtos de origem animal (excetofoiesgras)dos seguintes códigos, subposições e posições da NCM/SH: a) 02.01, 02.02, 0206.10.00, 0206.2 e 0210.20.00; b) 02.03, 0206.30.00, 0206.4, 0209.10 e 0210.1; c) 02.04 e 0210.99.20, carne caprina classificada no código 0210.99.90 e miudezas comestíveis de ovinos e caprinos classificadas nos códigos 0206.80.00 e 0206.90.00; d) 02.07, 0209.90.00 e 0210.99.1, exceto os produtos dos códigos 0207.43.00 e 0207.53.00 | H14: Cesta Básica Nacional de Alimentos — alíquota zero | I14: 200003 | J14: 200 | K14: 1 | M14: Art. 125 | N14: P0204
A15: Produto | B15: 0206.10.00 | C15: Só este NCM | E15: I | F15: 19 | G15: Carnes bovina, suína, ovina, caprina e de aves e produtos de origem animal (excetofoiesgras)dos seguintes códigos, subposições e posições da NCM/SH: a) 02.01, 02.02, 0206.10.00, 0206.2 e 0210.20.00; b) 02.03, 0206.30.00, 0206.4, 0209.10 e 0210.1; c) 02.04 e 0210.99.20, carne caprina classificada no código 0210.99.90 e miudezas comestíveis de ovinos e caprinos classificadas nos códigos 0206.80.00 e 0206.90.00; d) 02.07, 0209.90.00 e 0210.99.1, exceto os produtos dos códigos 0207.43.00 e 0207.53.00 | H15: Cesta Básica Nacional de Alimentos — alíquota zero | I15: 200003 | J15: 200 | K15: 1 | M15: Art. 125 | N15: P02061000
A16: Produto | B16: 0206.2 | C16: Todos os NCM que começam com 0206.2 | E16: I | F16: 19 | G16: Carnes bovina, suína, ovina, caprina e de aves e produtos de origem animal (excetofoiesgras)dos seguintes códigos, subposições e posições da NCM/SH: a) 02.01, 02.02, 0206.10.00, 0206.2 e 0210.20.00; b) 02.03, 0206.30.00, 0206.4, 0209.10 e 0210.1; c) 02.04 e 0210.99.20, carne caprina classificada no código 0210.99.90 e miudezas comestíveis de ovinos e caprinos classificadas nos códigos 0206.80.00 e 0206.90.00; d) 02.07, 0209.90.00 e 0210.99.1, exceto os produtos dos códigos 0207.43.00 e 0207.53.00 | H16: Cesta Básica Nacional de Alimentos — alíquota zero | I16: 200003 | J16: 200 | K16: 1 | M16: Art. 125 | N16: P02062
A17: Produto | B17: 0206.30.00 | C17: Só este NCM | E17: I | F17: 19 | G17: Carnes bovina, suína, ovina, caprina e de aves e produtos de origem animal (excetofoiesgras)dos seguintes códigos, subposições e posições da NCM/SH: a) 02.01, 02.02, 0206.10.00, 0206.2 e 0210.20.00; b) 02.03, 0206.30.00, 0206.4, 0209.10 e 0210.1; c) 02.04 e 0210.99.20, carne caprina classificada no código 0210.99.90 e miudezas comestíveis de ovinos e caprinos classificadas nos códigos 0206.80.00 e 0206.90.00; d) 02.07, 0209.90.00 e 0210.99.1, exceto os produtos dos códigos 0207.43.00 e 0207.53.00 | H17: Cesta Básica Nacional de Alimentos — alíquota zero | I17: 200003 | J17: 200 | K17: 1 | M17: Art. 125 | N17: P02063000
... A20: Produto | B20: 0206.90.00 | C20: Só este NCM | E20: I | F20: 19 | G20: Carnes bovina, suína, ovina, caprina e de aves e produtos de origem animal (excetofoiesgras)dos seguintes códigos, subposições e posições da NCM/SH: a) 02.01, 02.02, 0206.10.00, 0206.2 e 0210.20.00; b) 02.03, 0206.30.00, 0206.4, 0209.10 e 0210.1; c) 02.04 e 0210.99.20, carne caprina classificada no código 0210.99.90 e miudezas comestíveis de ovinos e caprinos classificadas nos códigos 0206.80.00 e 0206.90.00; d) 02.07, 0209.90.00 e 0210.99.1, exceto os produtos dos códigos 0207.43.00 e 0207.53.00 | H20: Cesta Básica Nacional de Alimentos — alíquota zero | I20: 200003 | J20: 200 | K20: 1 | M20: Art. 125 | N20: P02069000
A21: Produto | B21: 0207 | C21: Todos os NCM que começam com 0207 | D21: 0207.43.00 | E21: I | F21: 19 | G21: Carnes bovina, suína, ovina, caprina e de aves e produtos de origem animal (excetofoiesgras)dos seguintes códigos, subposições e posições da NCM/SH: a) 02.01, 02.02, 0206.10.00, 0206.2 e 0210.20.00; b) 02.03, 0206.30.00, 0206.4, 0209.10 e 0210.1; c) 02.04 e 0210.99.20, carne caprina classificada no código 0210.99.90 e miudezas comestíveis de ovinos e caprinos classificadas nos códigos 0206.80.00 e 0206.90.00; d) 02.07, 0209.90.00 e 0210.99.1, exceto os produtos dos códigos 0207.43.00 e 0207.53.00 | H21: Cesta Básica Nacional de Alimentos — alíquota zero | I21: 200003 | J21: 200 | K21: 1 | M21: Art. 125 | N21: P0207
A22: Produto | B22: 0207 | C22: Todos os NCM que começam com 0207 | D22: 0207.53.00 | E22: I | F22: 19 | G22: Carnes bovina, suína, ovina, caprina e de aves e produtos de origem animal (excetofoiesgras)dos seguintes códigos, subposições e posições da NCM/SH: a) 02.01, 02.02, 0206.10.00, 0206.2 e 0210.20.00; b) 02.03, 0206.30.00, 0206.4, 0209.10 e 0210.1; c) 02.04 e 0210.99.20, carne caprina classificada no código 0210.99.90 e miudezas comestíveis de ovinos e caprinos classificadas nos códigos 0206.80.00 e 0206.90.00; d) 02.07, 0209.90.00 e 0210.99.1, exceto os produtos dos códigos 0207.43.00 e 0207.53.00 | H22: Cesta Básica Nacional de Alimentos — alíquota zero | I22: 200003 | J22: 200 | K22: 1 | M22: Art. 125 | N22: P0207
A23: Produto | B23: 0209.10 | C23: Todos os NCM que começam com 0209.10 | E23: I | F23: 19 | G23: Carnes bovina, suína, ovina, caprina e de aves e produtos de origem animal (excetofoiesgras)dos seguintes códigos, subposições e posições da NCM/SH: a) 02.01, 02.02, 0206.10.00, 0206.2 e 0210.20.00; b) 02.03, 0206.30.00, 0206.4, 0209.10 e 0210.1; c) 02.04 e 0210.99.20, carne caprina classificada no código 0210.99.90 e miudezas comestíveis de ovinos e caprinos classificadas nos códigos 0206.80.00 e 0206.90.00; d) 02.07, 0209.90.00 e 0210.99.1, exceto os produtos dos códigos 0207.43.00 e 0207.53.00 | H23: Cesta Básica Nacional de Alimentos — alíquota zero | I23: 200003 | J23: 200 | K23: 1 | M23: Art. 125 | N23: P020910
A24: Produto | B24: 0209.90.00 | C24: Só este NCM | E24: I | F24: 19 | G24: Carnes bovina, suína, ovina, caprina e de aves e produtos de origem animal (excetofoiesgras)dos seguintes códigos, subposições e posições da NCM/SH: a) 02.01, 02.02, 0206.10.00, 0206.2 e 0210.20.00; b) 02.03, 0206.30.00, 0206.4, 0209.10 e 0210.1; c) 02.04 e 0210.99.20, carne caprina classificada no código 0210.99.90 e miudezas comestíveis de ovinos e caprinos classificadas nos códigos 0206.80.00 e 0206.90.00; d) 02.07, 0209.90.00 e 0210.99.1, exceto os produtos dos códigos 0207.43.00 e 0207.53.00 | H24: Cesta Básica Nacional de Alimentos — alíquota zero | I24: 200003 | J24: 200 | K24: 1 | M24: Art. 125 | N24: P02099000
A25: Produto | B25: 0210 | C25: Todos os NCM que começam com 0210 | E25: IX | F25: 21 | G25: Alho em pó, sal mineralizado, farinhas de peixe, de ostra, de carne, de osso, de pena, de sangue e de víscera, calcário calcítico, gorduras e óleos animais, resíduos de óleo e de gordura de origem animal ou vegetal descartados por empresas do ramo alimentício, e DL-Metionina e seus análogos; todos destinados diretamente à fabricação de ração para animais ou diretamente à alimentação animal, exceto de animais domésticos | H25: Insumos agropecuários e aquícolas — redução de 60% | I25: 200038 | J25: 200 | K25: 0.6 | M25: Art. 138 | N25: P0210
A26: Produto | B26: 0210.1 | C26: Todos os NCM que começam com 0210.1 | E26: I | F26: 19 | G26: Carnes bovina, suína, ovina, caprina e de aves e produtos de origem animal (excetofoiesgras)dos seguintes códigos, subposições e posições da NCM/SH: a) 02.01, 02.02, 0206.10.00, 0206.2 e 0210.20.00; b) 02.03, 0206.30.00, 0206.4, 0209.10 e 0210.1; c) 02.04 e 0210.99.20, carne caprina classificada no código 0210.99.90 e miudezas comestíveis de ovinos e caprinos classificadas nos códigos 0206.80.00 e 0206.90.00; d) 02.07, 0209.90.00 e 0210.99.1, exceto os produtos dos códigos 0207.43.00 e 0207.53.00 | H26: Cesta Básica Nacional de Alimentos — alíquota zero | I26: 200003 | J26: 200 | K26: 1 | M26: Art. 125 | N26: P02101
A27: Produto | B27: 0210.20.00 | C27: Só este NCM | E27: I | H27: Cesta Básica Nacional de Alimentos — alíquota zero | I27: 200003 | J27: 200 | K27: 1 | M27: Art. 125 | N27: P02102000
A28: Produto | B28: 0210.99.1 | C28: Todos os NCM que começam com 0210.99.1 | E28: I | F28: 19 | G28: Carnes bovina, suína, ovina, caprina e de aves e produtos de origem animal (excetofoiesgras)dos seguintes códigos, subposições e posições da NCM/SH: a) 02.01, 02.02, 0206.10.00, 0206.2 e 0210.20.00; b) 02.03, 0206.30.00, 0206.4, 0209.10 e 0210.1; c) 02.04 e 0210.99.20, carne caprina classificada no código 0210.99.90 e miudezas comestíveis de ovinos e caprinos classificadas nos códigos 0206.80.00 e 0206.90.00; d) 02.07, 0209.90.00 e 0210.99.1, exceto os produtos dos códigos 0207.43.00 e 0207.53.00 | H28: Cesta Básica Nacional de Alimentos — alíquota zero | I28: 200003 | J28: 200 | K28: 1 | M28: Art. 125 | N28: P0210991
A29: Produto | B29: 0210.99.20 | C29: Só este NCM | E29: I | F29: 19 | G29: Carnes bovina, suína, ovina, caprina e de aves e produtos de origem animal (excetofoiesgras)dos seguintes códigos, subposições e posições da NCM/SH: a) 02.01, 02.02, 0206.10.00, 0206.2 e 0210.20.00; b) 02.03, 0206.30.00, 0206.4, 0209.10 e 0210.1; c) 02.04 e 0210.99.20, carne caprina classificada no código 0210.99.90 e miudezas comestíveis de ovinos e caprinos classificadas nos códigos 0206.80.00 e 0206.90.00; d) 02.07, 0209.90.00 e 0210.99.1, exceto os produtos dos códigos 0207.43.00 e 0207.53.00 | H29: Cesta Básica Nacional de Alimentos — alíquota zero | I29: 200003 | J29: 200 | K29: 1 | M29: Art. 125 | N29: P02109920
A30: Produto | B30: 0210.99.90 | C30: Só este NCM | E30: I | F30: 19 | G30: Carnes bovina, suína, ovina, caprina e de aves e produtos de origem animal (excetofoiesgras)dos seguintes códigos, subposições e posições da NCM/SH: a) 02.01, 02.02, 0206.10.00, 0206.2 e 0210.20.00; b) 02.03, 0206.30.00, 0206.4, 0209.10 e 0210.1; c) 02.04 e 0210.99.20, carne caprina classificada no código 0210.99.90 e miudezas comestíveis de ovinos e caprinos classificadas nos códigos 0206.80.00 e 0206.90.00; d) 02.07, 0209.90.00 e 0210.99.1, exceto os produtos dos códigos 0207.43.00 e 0207.53.00 | H30: Cesta Básica Nacional de Alimentos — alíquota zero | I30: 200003 | J30: 200 | K30: 1 | M30: Art. 125 | N30: P02109990
A31: Produto | B31: 0302 | C31: Todos os NCM que começam com 0302 | D31: 0302.1 | E31: I | F31: 20 | G31: Peixes e carnes de peixes (exceto salmonídeos, atuns, bacalhaus, hadoque, saithe e ovas e outros subprodutos) dos seguintes códigos, subposições e posições da NCM/SH: a) 03.02; exceto os produtos das subposições e dos códigos 0302.1, 0302.3, 0302.51.00, 0302.52.00, 0302.53.00 e 0302.9 da NCM/SH; b) 03.03; exceto os produtos das subposições e dos códigos 0303.1, 0303.4, 0303.63.00, 0303.64.00, 0303.65.00 e 0303.9 da NCM/SH; c) 03.04; exceto os salmonídeos, atuns, bacalhaus, hadoque e saithe classificados nas subposições 0304.4, 0304.5, 0304.7, 0304.8 e 0304.9 da NCM/SH | H31: Cesta Básica Nacional de Alimentos — alíquota zero | I31: 200003 | J31: 200 | K31: 1 | M31: Art. 125 | N31: P0302
A32: Produto | B32: 0302 | C32: Todos os NCM que começam com 0302 | D32: 0302.3 | E32: I | F32: 20 | G32: Peixes e carnes de peixes (exceto salmonídeos, atuns, bacalhaus, hadoque, saithe e ovas e outros subprodutos) dos seguintes códigos, subposições e posições da NCM/SH: a) 03.02; exceto os produtos das subposições e dos códigos 0302.1, 0302.3, 0302.51.00, 0302.52.00, 0302.53.00 e 0302.9 da NCM/SH; b) 03.03; exceto os produtos das subposições e dos códigos 0303.1, 0303.4, 0303.63.00, 0303.64.00, 0303.65.00 e 0303.9 da NCM/SH; c) 03.04; exceto os salmonídeos, atuns, bacalhaus, hadoque e saithe classificados nas subposições 0304.4, 0304.5, 0304.7, 0304.8 e 0304.9 da NCM/SH | H32: Cesta Básica Nacional de Alimentos — alíquota zero | I32: 200003 | J32: 200 | K32: 1 | M32: Art. 125 | N32: P0302
A33: Produto | B33: 0302 | C33: Todos os NCM que começam com 0302 | D33: 0302.51.00 | E33: I | F33: 20 | G33: Peixes e carnes de peixes (exceto salmonídeos, atuns, bacalhaus, hadoque, saithe e ovas e outros subprodutos) dos seguintes códigos, subposições e posições da NCM/SH: a) 03.02; exceto os produtos das subposições e dos códigos 0302.1, 0302.3, 0302.51.00, 0302.52.00, 0302.53.00 e 0302.9 da NCM/SH; b) 03.03; exceto os produtos das subposições e dos códigos 0303.1, 0303.4, 0303.63.00, 0303.64.00, 0303.65.00 e 0303.9 da NCM/SH; c) 03.04; exceto os salmonídeos, atuns, bacalhaus, hadoque e saithe classificados nas subposições 0304.4, 0304.5, 0304.7, 0304.8 e 0304.9 da NCM/SH | H33: Cesta Básica Nacional de Alimentos — alíquota zero | I33: 200003 | J33: 200 | K33: 1 | M33: Art. 125 | N33: P0302
A34: Produto | B34: 0302 | C34: Todos os NCM que começam com 0302 | D34: 0302.52.00 | E34: I | F34: 20 | G34: Peixes e carnes de peixes (exceto salmonídeos, atuns, bacalhaus, hadoque, saithe e ovas e outros subprodutos) dos seguintes códigos, subposições e posições da NCM/SH: a) 03.02; exceto os produtos das subposições e dos códigos 0302.1, 0302.3, 0302.51.00, 0302.52.00, 0302.53.00 e 0302.9 da NCM/SH; b) 03.03; exceto os produtos das subposições e dos códigos 0303.1, 0303.4, 0303.63.00, 0303.64.00, 0303.65.00 e 0303.9 da NCM/SH; c) 03.04; exceto os salmonídeos, atuns, bacalhaus, hadoque e saithe classificados nas subposições 0304.4, 0304.5, 0304.7, 0304.8 e 0304.9 da NCM/SH | H34: Cesta Básica Nacional de Alimentos — alíquota zero | I34: 200003 | J34: 200 | K34: 1 | M34: Art. 125 | N34: P0302
A35: Produto | B35: 0302 | C35: Todos os NCM que começam com 0302 | D35: 0302.53.00 | E35: I | F35: 20 | G35: Peixes e carnes de peixes (exceto salmonídeos, atuns, bacalhaus, hadoque, saithe e ovas e outros subprodutos) dos seguintes códigos, subposições e posições da NCM/SH: a) 03.02; exceto os produtos das subposições e dos códigos 0302.1, 0302.3, 0302.51.00, 0302.52.00, 0302.53.00 e 0302.9 da NCM/SH; b) 03.03; exceto os produtos das subposições e dos códigos 0303.1, 0303.4, 0303.63.00, 0303.64.00, 0303.65.00 e 0303.9 da NCM/SH; c) 03.04; exceto os salmonídeos, atuns, bacalhaus, hadoque e saithe classificados nas subposições 0304.4, 0304.5, 0304.7, 0304.8 e 0304.9 da NCM/SH | H35: Cesta Básica Nacional de Alimentos — alíquota zero | I35: 200003 | J35: 200 | K35: 1 | M35: Art. 125 | N35: P0302
A36: Produto | B36: 0302 | C36: Todos os NCM que começam com 0302 | D36: 0302.9 | E36: I | F36: 20 | G36: Peixes e carnes de peixes (exceto salmonídeos, atuns, bacalhaus, hadoque, saithe e ovas e outros subprodutos) dos seguintes códigos, subposições e posições da NCM/SH: a) 03.02; exceto os produtos das subposições e dos códigos 0302.1, 0302.3, 0302.51.00, 0302.52.00, 0302.53.00 e 0302.9 da NCM/SH; b) 03.03; exceto os produtos das subposições e dos códigos 0303.1, 0303.4, 0303.63.00, 0303.64.00, 0303.65.00 e 0303.9 da NCM/SH; c) 03.04; exceto os salmonídeos, atuns, bacalhaus, hadoque e saithe classificados nas subposições 0304.4, 0304.5, 0304.7, 0304.8 e 0304.9 da NCM/SH | H36: Cesta Básica Nacional de Alimentos — alíquota zero | I36: 200003 | J36: 200 | K36: 1 | M36: Art. 125 | N36: P0302
A37: Produto | B37: 0303 | C37: Todos os NCM que começam com 0303 | D37: 0303.1 | E37: I | F37: 20 | G37: Peixes e carnes de peixes (exceto salmonídeos, atuns, bacalhaus, hadoque, saithe e ovas e outros subprodutos) dos seguintes códigos, subposições e posições da NCM/SH: a) 03.02; exceto os produtos das subposições e dos códigos 0302.1, 0302.3, 0302.51.00, 0302.52.00, 0302.53.00 e 0302.9 da NCM/SH; b) 03.03; exceto os produtos das subposições e dos códigos 0303.1, 0303.4, 0303.63.00, 0303.64.00, 0303.65.00 e 0303.9 da NCM/SH; c) 03.04; exceto os salmonídeos, atuns, bacalhaus, hadoque e saithe classificados nas subposições 0304.4, 0304.5, 0304.7, 0304.8 e 0304.9 da NCM/SH | H37: Cesta Básica Nacional de Alimentos — alíquota zero | I37: 200003 | J37: 200 | K37: 1 | M37: Art. 125 | N37: P0303
A38: Produto | B38: 0303 | C38: Todos os NCM que começam com 0303 | D38: 0303.4 | E38: I | F38: 20 | G38: Peixes e carnes de peixes (exceto salmonídeos, atuns, bacalhaus, hadoque, saithe e ovas e outros subprodutos) dos seguintes códigos, subposições e posições da NCM/SH: a) 03.02; exceto os produtos das subposições e dos códigos 0302.1, 0302.3, 0302.51.00, 0302.52.00, 0302.53.00 e 0302.9 da NCM/SH; b) 03.03; exceto os produtos das subposições e dos códigos 0303.1, 0303.4, 0303.63.00, 0303.64.00, 0303.65.00 e 0303.9 da NCM/SH; c) 03.04; exceto os salmonídeos, atuns, bacalhaus, hadoque e saithe classificados nas subposições 0304.4, 0304.5, 0304.7, 0304.8 e 0304.9 da NCM/SH | H38: Cesta Básica Nacional de Alimentos — alíquota zero | I38: 200003 | J38: 200 | K38: 1 | M38: Art. 125 | N38: P0303
A39: Produto | B39: 0303 | C39: Todos os NCM que começam com 0303 | D39: 0303.63.00 | E39: I | F39: 20 | G39: Peixes e carnes de peixes (exceto salmonídeos, atuns, bacalhaus, hadoque, saithe e ovas e outros subprodutos) dos seguintes códigos, subposições e posições da NCM/SH: a) 03.02; exceto os produtos das subposições e dos códigos 0302.1, 0302.3, 0302.51.00, 0302.52.00, 0302.53.00 e 0302.9 da NCM/SH; b) 03.03; exceto os produtos das subposições e dos códigos 0303.1, 0303.4, 0303.63.00, 0303.64.00, 0303.65.00 e 0303.9 da NCM/SH; c) 03.04; exceto os salmonídeos, atuns, bacalhaus, hadoque e saithe classificados nas subposições 0304.4, 0304.5, 0304.7, 0304.8 e 0304.9 da NCM/SH | H39: Cesta Básica Nacional de Alimentos — alíquota zero | I39: 200003 | J39: 200 | K39: 1 | M39: Art. 125 | N39: P0303
A40: Produto | B40: 0303 | C40: Todos os NCM que começam com 0303 | D40: 0303.64.00 | E40: I | F40: 20 | G40: Peixes e carnes de peixes (exceto salmonídeos, atuns, bacalhaus, hadoque, saithe e ovas e outros subprodutos) dos seguintes códigos, subposições e posições da NCM/SH: a) 03.02; exceto os produtos das subposições e dos códigos 0302.1, 0302.3, 0302.51.00, 0302.52.00, 0302.53.00 e 0302.9 da NCM/SH; b) 03.03; exceto os produtos das subposições e dos códigos 0303.1, 0303.4, 0303.63.00, 0303.64.00, 0303.65.00 e 0303.9 da NCM/SH; c) 03.04; exceto os salmonídeos, atuns, bacalhaus, hadoque e saithe classificados nas subposições 0304.4, 0304.5, 0304.7, 0304.8 e 0304.9 da NCM/SH | H40: Cesta Básica Nacional de Alimentos — alíquota zero | I40: 200003 | J40: 200 | K40: 1 | M40: Art. 125 | N40: P0303
A41: Produto | B41: 0303 | C41: Todos os NCM que começam com 0303 | D41: 0303.65.00 | E41: I | F41: 20 | G41: Peixes e carnes de peixes (exceto salmonídeos, atuns, bacalhaus, hadoque, saithe e ovas e outros subprodutos) dos seguintes códigos, subposições e posições da NCM/SH: a) 03.02; exceto os produtos das subposições e dos códigos 0302.1, 0302.3, 0302.51.00, 0302.52.00, 0302.53.00 e 0302.9 da NCM/SH; b) 03.03; exceto os produtos das subposições e dos códigos 0303.1, 0303.4, 0303.63.00, 0303.64.00, 0303.65.00 e 0303.9 da NCM/SH; c) 03.04; exceto os salmonídeos, atuns, bacalhaus, hadoque e saithe classificados nas subposições 0304.4, 0304.5, 0304.7, 0304.8 e 0304.9 da NCM/SH | H41: Cesta Básica Nacional de Alimentos — alíquota zero | I41: 200003 | J41: 200 | K41: 1 | M41: Art. 125 | N41: P0303
A42: Produto | B42: 0303 | C42: Todos os NCM que começam com 0303 | D42: 0303.9 | E42: I | F42: 20 | G42: Peixes e carnes de peixes (exceto salmonídeos, atuns, bacalhaus, hadoque, saithe e ovas e outros subprodutos) dos seguintes códigos, subposições e posições da NCM/SH: a) 03.02; exceto os produtos das subposições e dos códigos 0302.1, 0302.3, 0302.51.00, 0302.52.00, 0302.53.00 e 0302.9 da NCM/SH; b) 03.03; exceto os produtos das subposições e dos códigos 0303.1, 0303.4, 0303.63.00, 0303.64.00, 0303.65.00 e 0303.9 da NCM/SH; c) 03.04; exceto os salmonídeos, atuns, bacalhaus, hadoque e saithe classificados nas subposições 0304.4, 0304.5, 0304.7, 0304.8 e 0304.9 da NCM/SH | H42: Cesta Básica Nacional de Alimentos — alíquota zero | I42: 200003 | J42: 200 | K42: 1 | M42: Art. 125 | N42: P0303
...

Sheet CFOP
A1: CFOP mais usados — tipo de operação e orientação para IBS/CBS
A2: Primeiro dígito: 1 = entrada no estado, 2 = entrada de outro estado, 3 = entrada do exterior; 5 = saída no estado, 6 = saída para outro estado, 7 = saída para o exterior. O CFOP é da OPERAÇÃO, não do produto: o mesmo produto sai com CFOPs diferentes conforme a venda, a devolução, a remessa…
A3: Tabela de CFOP (Convênio s/nº de 15/12/1970, com a redação do Ajuste SINIEF 07/2001 e alterações). Descrições resumidas; conferir a tabela oficial. A coluna de IBS/CBS é orientação inicial de estudo (LC 214/2025), a confirmar caso a caso.
A4: CFOP | B4: Sentido | C4: Equivalentes | D4: Descrição | E4: Tipo de operação | F4: IBS/CBS — orientação inicial
A5: 5101 | B5: Saída (no estado) | C5: 6101 / 7101 | D5: Venda de produção do estabelecimento | E5: Venda | F5: Tributa (fornecimento oneroso). Classificação pelo produto e pelo comprador.
A6: 5102 | B6: Saída (no estado) | C6: 6102 / 7102 | D6: Venda de mercadoria adquirida ou recebida de terceiros | E6: Venda | F6: Tributa. Classificação pelo produto e pelo comprador.
A7: 5103 | B7: Saída (no estado) | C7: 6103 | D7: Venda de produção do estabelecimento, efetuada fora do estabelecimento | E7: Venda | F7: Tributa.
A8: 5104 | B8: Saída (no estado) | C8: 6104 | D8: Venda de mercadoria adquirida ou recebida de terceiros, efetuada fora do estabelecimento | E8: Venda | F8: Tributa.
A9: 5105 | B9: Saída (no estado) | C9: 6105 | D9: Venda de produção do estabelecimento que não deva por ele transitar | E9: Venda | F9: Tributa.
A10: 5106 | B10: Saída (no estado) | C10: 6106 | D10: Venda de mercadoria adquirida ou recebida de terceiros, que não deva por ele transitar | E10: Venda | F10: Tributa.
A11: 6107 | B11: Saída (outro estado) | C11: — | D11: Venda de produção do estabelecimento, destinada a não contribuinte (outro estado) | E11: Venda | F11: Tributa. IBS do destino (estado/município do comprador).
A12: 6108 | B12: Saída (outro estado) | C12: — | D12: Venda de mercadoria adquirida ou recebida de terceiros, destinada a não contribuinte (outro estado) | E12: Venda | F12: Tributa. IBS do destino (estado/município do comprador).
A13: 6109 | B13: Saída (outro estado) | C13: — | D13: Venda de produção do estabelecimento, destinada à Zona Franca de Manaus ou Áreas de Livre Comércio | E13: Venda (ZFM/ALC) | F13: Regime da ZFM/ALC — tratamento próprio (conferir).
A14: 6110 | B14: Saída (outro estado) | C14: — | D14: Venda de mercadoria adquirida ou recebida de terceiros, destinada à Zona Franca de Manaus ou Áreas de Livre Comércio | E14: Venda (ZFM/ALC) | F14: Regime da ZFM/ALC — tratamento próprio (conferir).
A15: 5116 | B15: Saída (no estado) | C15: 6116 | D15: Venda de produção do estabelecimento originada de encomenda para entrega futura | E15: Venda (entrega futura) | F15: Tributa na entrega; conferir o tratamento do pagamento antecipado.
... A74: 1949 | B74: Entrada (no estado) | C74: 2949 / 3949 | D74: Outra entrada de mercadoria ou prestação de serviço não especificada | E74: Outros | F74: Genérico: sempre revisar qual é a operação de verdade.

Sheet Modelo de catálogo
A1: Modelo de catálogo — um produto ou serviço por linha
A2: Preencha as colunas AMARELAS (A a F e N a S). As colunas CINZAS (G a M) são calculadas pela aba “Referência LC 214”: mostram a regra mais específica que o código encontrou. Quando há mais de uma regra (coluna G maior que 1) ou uma condição (coluna L), confira o item do anexo antes de decidir.
A3: A sugestão não considera as exceções dos anexos nem a descrição do produto: a decisão final (colunas O e P) é do escritório. Digite o NCM com 8 dígitos e a NBS com 9 (pode ser com ou sem pontos). As linhas 7 a 10 são exemplos — pode apagar.
A6: Código interno | B6: Descrição do produto ou serviço | C6: Tipo | D6: NCM (produto) ou NBS (serviço) | E6: GTIN (código de barras) | F6: Unidade | G6: Regras na LC 214 | H6: Sugestão (cClassTrib) | I6: Tratamento sugerido | J6: Redução | K6: Item do anexo | L6: Condição | M6: Atenção | N6: Vende para órgão público ou entidade SUS? | O6: cClassTrib escolhido | P6: Status | Q6: Aprovado por | R6: Data | S6: Observação | T6: Chave | U6: Linha da regra
A7: ARR-005 | B7: Arroz branco tipo 1, pacote 5 kg | C7: Produto | D7: 1006.30.21 | E7: 7890000000017 | F7: PCT | G7: =IF(T7="","",SUMPRODUCT(--(LEFT(T7,LEN('Referência LC 214'!$N$6:$N$967))='Referência LC 214'!$N$6:$N$967))) -> 6 | H7: =IF(T7="","",IF(U7="","000001",INDEX('Referência LC 214'!$I$6:$I$967,U7))) -> 200003 | I7: =IF(T7="","",IF(U7="","Sem anexo: tributação integral",INDEX('Referência LC 214'!$H$6:$H$967,U7))) -> Cesta Básica Nacional de Alimentos — alíquota zero | J7: =IF(T7="","",IF(U7="",0,INDEX('Referência LC 214'!$K$6:$K$967,U7))) -> 1 | K7: =IF(OR(T7="",U7=""),"","Anexo "&INDEX('Referência LC 214'!$E$6:$E$967,U7)&", item "&INDEX('Referência LC 214'!$F$6:$F$967,U7)&": "&INDEX('Referência LC 214'!$G$6:$G$967,U7)) -> Anexo I, item 1: Arroz das subposições 1006.20 e 1006.30 e do código 1006.40.00 da NCM/SH | L7: =IF(OR(T7="",U7=""),"",IF(INDEX('Referência LC 214'!$L$6:$L$967,U7)&""<>"",INDEX('Referência LC 214'!$L$6:$L$967,U7)&"",IF(SUMPRODUCT((LEFT(T7,LEN('Referência LC 214'!$N$6:$N$967))='Referência LC 214'!$N$6:$N$967)*('Referência LC 214'!$L$6:$L$967<>""))>0,"Há outro tratamento só para alguns compradores (ex.: órgão público/SUS) — veja a referência",""))) | M7: =IF(T7="","",IF(AND(C7<>"Serviço",LEN(T7)-1<>8),"NCM deve ter 8 dígitos",IF(AND(C7="Serviço",LEN(T7)-1<>9),"NBS deve ter 9 dígitos",IF(L7<>"","Benefício depende do comprador: confira a coluna N",IF(G7>1,"Mais de uma regra: confira o item do anexo na referência",IF(G7=0,"Sem redução na LC 214","Confira se o produto é o descrito no item")))))) -> Mais de uma regra: confira o item do anexo na referência | N7: Não | O7: 200003 | P7: Aprovado | Q7: Escritório | S7: Exemplo — pode apagar | T7: =IF(D7="","",IF(C7="Serviço","S","P")&SUBSTITUTE(SUBSTITUTE(SUBSTITUTE(D7,".",""),"-","")," ","")) -> P10063021 | U7: =IF(T7="","",IFERROR(MATCH(LEFT(T7,10),'Referência LC 214'!$N$6:$N$967,0),IFERROR(MATCH(LEFT(T7,9),'Referência LC 214'!$N$6:$N$967,0),IFERROR(MATCH(LEFT(T7,8),'Referência LC 214'!$N$6:$N$967,0),IFERROR(MATCH(LEFT(T7,7),'Referência LC 214'!$N$6:$N$967,0),IFERROR(MATCH(LEFT(T7,6),'Referência LC 214'!$N$6:$N$967,0),IFERROR(MATCH(LEFT(T7,5),'Referência LC 214'!$N$6:$N$967,0),IFERROR(MATCH(LEFT(T7,4),'Referência LC 214'!$N$6:$N$967,0),IFERROR(MATCH(LEFT(T7,3),'Referência LC 214'!$N$6:$N$967,0),""))))))))) -> 152
A8: SER-010 | B8: Seringa descartável 10 ml com agulha | C8: Produto | D8: 9018.31.19 | F8: UN | G8: =IF(T8="","",SUMPRODUCT(--(LEFT(T8,LEN('Referência LC 214'!$N$6:$N$967))='Referência LC 214'!$N$6:$N$967))) -> 2 | H8: =IF(T8="","",IF(U8="","000001",INDEX('Referência LC 214'!$I$6:$I$967,U8))) -> 200030 | I8: =IF(T8="","",IF(U8="","Sem anexo: tributação integral",INDEX('Referência LC 214'!$H$6:$H$967,U8))) -> Dispositivos médicos — redução de 60% | J8: =IF(T8="","",IF(U8="",0,INDEX('Referência LC 214'!$K$6:$K$967,U8))) -> 0.6 | K8: =IF(OR(T8="",U8=""),"","Anexo "&INDEX('Referência LC 214'!$E$6:$E$967,U8)&", item "&INDEX('Referência LC 214'!$F$6:$F$967,U8)&": "&INDEX('Referência LC 214'!$G$6:$G$967,U8)) -> Anexo IV, item 59: Seringas, mesmo com agulhas | L8: =IF(OR(T8="",U8=""),"",IF(INDEX('Referência LC 214'!$L$6:$L$967,U8)&""<>"",INDEX('Referência LC 214'!$L$6:$L$967,U8)&"",IF(SUMPRODUCT((LEFT(T8,LEN('Referência LC 214'!$N$6:$N$967))='Referência LC 214'!$N$6:$N$967)*('Referência LC 214'!$L$6:$L$967<>""))>0,"Há outro tratamento só para alguns compradores (ex.: órgão público/SUS) — veja a referência",""))) -> Há outro tratamento só para alguns compradores (ex.: órgão público/SUS) — veja a referência | M8: =IF(T8="","",IF(AND(C8<>"Serviço",LEN(T8)-1<>8),"NCM deve ter 8 dígitos",IF(AND(C8="Serviço",LEN(T8)-1<>9),"NBS deve ter 9 dígitos",IF(L8<>"","Benefício depende do comprador: confira a coluna N",IF(G8>1,"Mais de uma regra: confira o item do anexo na referência",IF(G8=0,"Sem redução na LC 214","Confira se o produto é o descrito no item")))))) -> Benefício depende do comprador: confira a coluna N | N8: Sim | P8: Revisar | S8: Exemplo: definir 200030 (geral) e 200005 (órgão público/SUS) | T8: =IF(D8="","",IF(C8="Serviço","S","P")&SUBSTITUTE(SUBSTITUTE(SUBSTITUTE(D8,".",""),"-","")," ","")) -> P90183119 | U8: =IF(T8="","",IFERROR(MATCH(LEFT(T8,10),'Referência LC 214'!$N$6:$N$967,0),IFERROR(MATCH(LEFT(T8,9),'Referência LC 214'!$N$6:$N$967,0),IFERROR(MATCH(LEFT(T8,8),'Referência LC 214'!$N$6:$N$967,0),IFERROR(MATCH(LEFT(T8,7),'Referência LC 214'!$N$6:$N$967,0),IFERROR(MATCH(LEFT(T8,6),'Referência LC 214'!$N$6:$N$967,0),IFERROR(MATCH(LEFT(T8,5),'Referência LC 214'!$N$6:$N$967,0),IFERROR(MATCH(LEFT(T8,4),'Referência LC 214'!$N$6:$N$967,0),IFERROR(MATCH(LEFT(T8,3),'Referência LC 214'!$N$6:$N$967,0),""))))))))) -> 679
A9: NB-001 | B9: Notebook 14 polegadas | C9: Produto | D9: 8471.30.12 | F9: UN | G9: =IF(T9="","",SUMPRODUCT(--(LEFT(T9,LEN('Referência LC 214'!$N$6:$N$967))='Referência LC 214'!$N$6:$N$967))) -> 0 | H9: =IF(T9="","",IF(U9="","000001",INDEX('Referência LC 214'!$I$6:$I$967,U9))) -> 000001 | I9: =IF(T9="","",IF(U9="","Sem anexo: tributação integral",INDEX('Referência LC 214'!$H$6:$H$967,U9))) -> Sem anexo: tributação integral | J9: =IF(T9="","",IF(U9="",0,INDEX('Referência LC 214'!$K$6:$K$967,U9))) -> 0 | K9: =IF(OR(T9="",U9=""),"","Anexo "&INDEX('Referência LC 214'!$E$6:$E$967,U9)&", item "&INDEX('Referência LC 214'!$F$6:$F$967,U9)&": "&INDEX('Referência LC 214'!$G$6:$G$967,U9)) | L9: =IF(OR(T9="",U9=""),"",IF(INDEX('Referência LC 214'!$L$6:$L$967,U9)&""<>"",INDEX('Referência LC 214'!$L$6:$L$967,U9)&"",IF(SUMPRODUCT((LEFT(T9,LEN('Referência LC 214'!$N$6:$N$967))='Referência LC 214'!$N$6:$N$967)*('Referência LC 214'!$L$6:$L$967<>""))>0,"Há outro tratamento só para alguns compradores (ex.: órgão público/SUS) — veja a referência",""))) | M9: =IF(T9="","",IF(AND(C9<>"Serviço",LEN(T9)-1<>8),"NCM deve ter 8 dígitos",IF(AND(C9="Serviço",LEN(T9)-1<>9),"NBS deve ter 9 dígitos",IF(L9<>"","Benefício depende do comprador: confira a coluna N",IF(G9>1,"Mais de uma regra: confira o item do anexo na referência",IF(G9=0,"Sem redução na LC 214","Confira se o produto é o descrito no item")))))) -> Sem redução na LC 214 | N9: Não | O9: 000001 | P9: Aprovado | Q9: Escritório | S9: Exemplo — pode apagar | T9: =IF(D9="","",IF(C9="Serviço","S","P")&SUBSTITUTE(SUBSTITUTE(SUBSTITUTE(D9,".",""),"-","")," ","")) -> P84713012 | U9: =IF(T9="","",IFERROR(MATCH(LEFT(T9,10),'Referência LC 214'!$N$6:$N$967,0),IFERROR(MATCH(LEFT(T9,9),'Referência LC 214'!$N$6:$N$967,0),IFERROR(MATCH(LEFT(T9,8),'Referência LC 214'!$N$6:$N$967,0),IFERROR(MATCH(LEFT(T9,7),'Referência LC 214'!$N$6:$N$967,0),IFERROR(MATCH(LEFT(T9,6),'Referência LC 214'!$N$6:$N$967,0),IFERROR(MATCH(LEFT(T9,5),'Referência LC 214'!$N$6:$N$967,0),IFERROR(MATCH(LEFT(T9,4),'Referência LC 214'!$N$6:$N$967,0),IFERROR(MATCH(LEFT(T9,3),'Referência LC 214'!$N$6:$N$967,0),"")))))))))
A10: SV-EDU | B10: Mensalidade de ensino infantil | C10: Serviço | D10: 1.2201.20.00 | F10: MES | G10: =IF(T10="","",SUMPRODUCT(--(LEFT(T10,LEN('Referência LC 214'!$N$6:$N$967))='Referência LC 214'!$N$6:$N$967))) -> 1 | H10: =IF(T10="","",IF(U10="","000001",INDEX('Referência LC 214'!$I$6:$I$967,U10))) -> 200028 | I10: =IF(T10="","",IF(U10="","Sem anexo: tributação integral",INDEX('Referência LC 214'!$H$6:$H$967,U10))) -> Serviços de educação — redução de 60% | J10: =IF(T10="","",IF(U10="",0,INDEX('Referência LC 214'!$K$6:$K$967,U10))) -> 0.6 | K10: =IF(OR(T10="",U10=""),"","Anexo "&INDEX('Referência LC 214'!$E$6:$E$967,U10)&", item "&INDEX('Referência LC 214'!$F$6:$F$967,U10)&": "&INDEX('Referência LC 214'!$G$6:$G$967,U10)) -> Anexo II, item 1: Ensino Infantil, inclusive creche e pré-escola | L10: =IF(OR(T10="",U10=""),"",IF(INDEX('Referência LC 214'!$L$6:$L$967,U10)&""<>"",INDEX('Referência LC 214'!$L$6:$L$967,U10)&"",IF(SUMPRODUCT((LEFT(T10,LEN('Referência LC 214'!$N$6:$N$967))='Referência LC 214'!$N$6:$N$967)*('Referência LC 214'!$L$6:$L$967<>""))>0,"Há outro tratamento só para alguns compradores (ex.: órgão público/SUS) — veja a referência",""))) | M10: =IF(T10="","",IF(AND(C10<>"Serviço",LEN(T10)-1<>8),"NCM deve ter 8 dígitos",IF(AND(C10="Serviço",LEN(T10)-1<>9),"NBS deve ter 9 dígitos",IF(L10<>"","Benefício depende do comprador: confira a coluna N",IF(G10>1,"Mais de uma regra: confira o item do anexo na referência",IF(G10=0,"Sem redução na LC 214","Confira se o produto é o descrito no item")))))) -> Confira se o produto é o descrito no item | N10: Não | P10: Pendente | S10: Exemplo — pode apagar | T10: =IF(D10="","",IF(C10="Serviço","S","P")&SUBSTITUTE(SUBSTITUTE(SUBSTITUTE(D10,".",""),"-","")," ","")) -> S122012000 | U10: =IF(T10="","",IFERROR(MATCH(LEFT(T10,10),'Referência LC 214'!$N$6:$N$967,0),IFERROR(MATCH(LEFT(T10,9),'Referência LC 214'!$N$6:$N$967,0),IFERROR(MATCH(LEFT(T10,8),'Referência LC 214'!$N$6:$N$967,0),IFERROR(MATCH(LEFT(T10,7),'Referência LC 214'!$N$6:$N$967,0),IFERROR(MATCH(LEFT(T10,6),'Referência LC 214'!$N$6:$N$967,0),IFERROR(MATCH(LEFT(T10,5),'Referência LC 214'!$N$6:$N$967,0),IFERROR(MATCH(LEFT(T10,4),'Referência LC 214'!$N$6:$N$967,0),IFERROR(MATCH(LEFT(T10,3),'Referência LC 214'!$N$6:$N$967,0),""))))))))) -> 916
G11: =IF(T11="","",SUMPRODUCT(--(LEFT(T11,LEN('Referência LC 214'!$N$6:$N$967))='Referência LC 214'!$N$6:$N$967))) | H11: =IF(T11="","",IF(U11="","000001",INDEX('Referência LC 214'!$I$6:$I$967,U11))) | I11: =IF(T11="","",IF(U11="","Sem anexo: tributação integral",INDEX('Referência LC 214'!$H$6:$H$967,U11))) | J11: =IF(T11="","",IF(U11="",0,INDEX('Referência LC 214'!$K$6:$K$967,U11))) | K11: =IF(OR(T11="",U11=""),"","Anexo "&INDEX('Referência LC 214'!$E$6:$E$967,U11)&", item "&INDEX('Referência LC 214'!$F$6:$F$967,U11)&": "&INDEX('Referência LC 214'!$G$6:$G$967,U11)) | L11: =IF(OR(T11="",U11=""),"",IF(INDEX('Referência LC 214'!$L$6:$L$967,U11)&""<>"",INDEX('Referência LC 214'!$L$6:$L$967,U11)&"",IF(SUMPRODUCT((LEFT(T11,LEN('Referência LC 214'!$N$6:$N$967))='Referência LC 214'!$N$6:$N$967)*('Referência LC 214'!$L$6:$L$967<>""))>0,"Há outro tratamento só para alguns compradores (ex.: órgão público/SUS) — veja a referência",""))) | M11: =IF(T11="","",IF(AND(C11<>"Serviço",LEN(T11)-1<>8),"NCM deve ter 8 dígitos",IF(AND(C11="Serviço",LEN(T11)-1<>9),"NBS deve ter 9 dígitos",IF(L11<>"","Benefício depende do comprador: confira a coluna N",IF(G11>1,"Mais de uma regra: confira o item do anexo na referência",IF(G11=0,"Sem redução na LC 214","Confira se o produto é o descrito no item")))))) | T11: =IF(D11="","",IF(C11="Serviço","S","P")&SUBSTITUTE(SUBSTITUTE(SUBSTITUTE(D11,".",""),"-","")," ","")) | U11: =IF(T11="","",IFERROR(MATCH(LEFT(T11,10),'Referência LC 214'!$N$6:$N$967,0),IFERROR(MATCH(LEFT(T11,9),'Referência LC 214'!$N$6:$N$967,0),IFERROR(MATCH(LEFT(T11,8),'Referência LC 214'!$N$6:$N$967,0),IFERROR(MATCH(LEFT(T11,7),'Referência LC 214'!$N$6:$N$967,0),IFERROR(MATCH(LEFT(T11,6),'Referência LC 214'!$N$6:$N$967,0),IFERROR(MATCH(LEFT(T11,5),'Referência LC 214'!$N$6:$N$967,0),IFERROR(MATCH(LEFT(T11,4),'Referência LC 214'!$N$6:$N$967,0),IFERROR(MATCH(LEFT(T11,3),'Referência LC 214'!$N$6:$N$967,0),"")))))))))
G12: =IF(T12="","",SUMPRODUCT(--(LEFT(T12,LEN('Referência LC 214'!$N$6:$N$967))='Referência LC 214'!$N$6:$N$967))) | H12: =IF(T12="","",IF(U12="","000001",INDEX('Referência LC 214'!$I$6:$I$967,U12))) | I12: =IF(T12="","",IF(U12="","Sem anexo: tributação integral",INDEX('Referência LC 214'!$H$6:$H$967,U12))) | J12: =IF(T12="","",IF(U12="",0,INDEX('Referência LC 214'!$K$6:$K$967,U12))) | K12: =IF(OR(T12="",U12=""),"","Anexo "&INDEX('Referência LC 214'!$E$6:$E$967,U12)&", item "&INDEX('Referência LC 214'!$F$6:$F$967,U12)&": "&INDEX('Referência LC 214'!$G$6:$G$967,U12)) | L12: =IF(OR(T12="",U12=""),"",IF(INDEX('Referência LC 214'!$L$6:$L$967,U12)&""<>"",INDEX('Referência LC 214'!$L$6:$L$967,U12)&"",IF(SUMPRODUCT((LEFT(T12,LEN('Referência LC 214'!$N$6:$N$967))='Referência LC 214'!$N$6:$N$967)*('Referência LC 214'!$L$6:$L$967<>""))>0,"Há outro tratamento só para alguns compradores (ex.: órgão público/SUS) — veja a referência",""))) | M12: =IF(T12="","",IF(AND(C12<>"Serviço",LEN(T12)-1<>8),"NCM deve ter 8 dígitos",IF(AND(C12="Serviço",LEN(T12)-1<>9),"NBS deve ter 9 dígitos",IF(L12<>"","Benefício depende do comprador: confira a coluna N",IF(G12>1,"Mais de uma regra: confira o item do anexo na referência",IF(G12=0,"Sem redução na LC 214","Confira se o produto é o descrito no item")))))) | T12: =IF(D12="","",IF(C12="Serviço","S","P")&SUBSTITUTE(SUBSTITUTE(SUBSTITUTE(D12,".",""),"-","")," ","")) | U12: =IF(T12="","",IFERROR(MATCH(LEFT(T12,10),'Referência LC 214'!$N$6:$N$967,0),IFERROR(MATCH(LEFT(T12,9),'Referência LC 214'!$N$6:$N$967,0),IFERROR(MATCH(LEFT(T12,8),'Referência LC 214'!$N$6:$N$967,0),IFERROR(MATCH(LEFT(T12,7),'Referência LC 214'!$N$6:$N$967,0),IFERROR(MATCH(LEFT(T12,6),'Referência LC 214'!$N$6:$N$967,0),IFERROR(MATCH(LEFT(T12,5),'Referência LC 214'!$N$6:$N$967,0),IFERROR(MATCH(LEFT(T12,4),'Referência LC 214'!$N$6:$N$967,0),IFERROR(MATCH(LEFT(T12,3),'Referência LC 214'!$N$6:$N$967,0),"")))))))))
G13: =IF(T13="","",SUMPRODUCT(--(LEFT(T13,LEN('Referência LC 214'!$N$6:$N$967))='Referência LC 214'!$N$6:$N$967))) | H13: =IF(T13="","",IF(U13="","000001",INDEX('Referência LC 214'!$I$6:$I$967,U13))) | I13: =IF(T13="","",IF(U13="","Sem anexo: tributação integral",INDEX('Referência LC 214'!$H$6:$H$967,U13))) | J13: =IF(T13="","",IF(U13="",0,INDEX('Referência LC 214'!$K$6:$K$967,U13))) | K13: =IF(OR(T13="",U13=""),"","Anexo "&INDEX('Referência LC 214'!$E$6:$E$967,U13)&", item "&INDEX('Referência LC 214'!$F$6:$F$967,U13)&": "&INDEX('Referência LC 214'!$G$6:$G$967,U13)) | L13: =IF(OR(T13="",U13=""),"",IF(INDEX('Referência LC 214'!$L$6:$L$967,U13)&""<>"",INDEX('Referência LC 214'!$L$6:$L$967,U13)&"",IF(SUMPRODUCT((LEFT(T13,LEN('Referência LC 214'!$N$6:$N$967))='Referência LC 214'!$N$6:$N$967)*('Referência LC 214'!$L$6:$L$967<>""))>0,"Há outro tratamento só para alguns compradores (ex.: órgão público/SUS) — veja a referência",""))) | M13: =IF(T13="","",IF(AND(C13<>"Serviço",LEN(T13)-1<>8),"NCM deve ter 8 dígitos",IF(AND(C13="Serviço",LEN(T13)-1<>9),"NBS deve ter 9 dígitos",IF(L13<>"","Benefício depende do comprador: confira a coluna N",IF(G13>1,"Mais de uma regra: confira o item do anexo na referência",IF(G13=0,"Sem redução na LC 214","Confira se o produto é o descrito no item")))))) | T13: =IF(D13="","",IF(C13="Serviço","S","P")&SUBSTITUTE(SUBSTITUTE(SUBSTITUTE(D13,".",""),"-","")," ","")) | U13: =IF(T13="","",IFERROR(MATCH(LEFT(T13,10),'Referência LC 214'!$N$6:$N$967,0),IFERROR(MATCH(LEFT(T13,9),'Referência LC 214'!$N$6:$N$967,0),IFERROR(MATCH(LEFT(T13,8),'Referência LC 214'!$N$6:$N$967,0),IFERROR(MATCH(LEFT(T13,7),'Referência LC 214'!$N$6:$N$967,0),IFERROR(MATCH(LEFT(T13,6),'Referência LC 214'!$N$6:$N$967,0),IFERROR(MATCH(LEFT(T13,5),'Referência LC 214'!$N$6:$N$967,0),IFERROR(MATCH(LEFT(T13,4),'Referência LC 214'!$N$6:$N$967,0),IFERROR(MATCH(LEFT(T13,3),'Referência LC 214'!$N$6:$N$967,0),"")))))))))
G14: =IF(T14="","",SUMPRODUCT(--(LEFT(T14,LEN('Referência LC 214'!$N$6:$N$967))='Referência LC 214'!$N$6:$N$967))) | H14: =IF(T14="","",IF(U14="","000001",INDEX('Referência LC 214'!$I$6:$I$967,U14))) | I14: =IF(T14="","",IF(U14="","Sem anexo: tributação integral",INDEX('Referência LC 214'!$H$6:$H$967,U14))) | J14: =IF(T14="","",IF(U14="",0,INDEX('Referência LC 214'!$K$6:$K$967,U14))) | K14: =IF(OR(T14="",U14=""),"","Anexo "&INDEX('Referência LC 214'!$E$6:$E$967,U14)&", item "&INDEX('Referência LC 214'!$F$6:$F$967,U14)&": "&INDEX('Referência LC 214'!$G$6:$G$967,U14)) | L14: =IF(OR(T14="",U14=""),"",IF(INDEX('Referência LC 214'!$L$6:$L$967,U14)&""<>"",INDEX('Referência LC 214'!$L$6:$L$967,U14)&"",IF(SUMPRODUCT((LEFT(T14,LEN('Referência LC 214'!$N$6:$N$967))='Referência LC 214'!$N$6:$N$967)*('Referência LC 214'!$L$6:$L$967<>""))>0,"Há outro tratamento só para alguns compradores (ex.: órgão público/SUS) — veja a referência",""))) | M14: =IF(T14="","",IF(AND(C14<>"Serviço",LEN(T14)-1<>8),"NCM deve ter 8 dígitos",IF(AND(C14="Serviço",LEN(T14)-1<>9),"NBS deve ter 9 dígitos",IF(L14<>"","Benefício depende do comprador: confira a coluna N",IF(G14>1,"Mais de uma regra: confira o item do anexo na referência",IF(G14=0,"Sem redução na LC 214","Confira se o produto é o descrito no item")))))) | T14: =IF(D14="","",IF(C14="Serviço","S","P")&SUBSTITUTE(SUBSTITUTE(SUBSTITUTE(D14,".",""),"-","")," ","")) | U14: =IF(T14="","",IFERROR(MATCH(LEFT(T14,10),'Referência LC 214'!$N$6:$N$967,0),IFERROR(MATCH(LEFT(T14,9),'Referência LC 214'!$N$6:$N$967,0),IFERROR(MATCH(LEFT(T14,8),'Referência LC 214'!$N$6:$N$967,0),IFERROR(MATCH(LEFT(T14,7),'Referência LC 214'!$N$6:$N$967,0),IFERROR(MATCH(LEFT(T14,6),'Referência LC 214'!$N$6:$N$967,0),IFERROR(MATCH(LEFT(T14,5),'Referência LC 214'!$N$6:$N$967,0),IFERROR(MATCH(LEFT(T14,4),'Referência LC 214'!$N$6:$N$967,0),IFERROR(MATCH(LEFT(T14,3),'Referência LC 214'!$N$6:$N$967,0),"")))))))))
G15: =IF(T15="","",SUMPRODUCT(--(LEFT(T15,LEN('Referência LC 214'!$N$6:$N$967))='Referência LC 214'!$N$6:$N$967))) | H15: =IF(T15="","",IF(U15="","000001",INDEX('Referência LC 214'!$I$6:$I$967,U15))) | I15: =IF(T15="","",IF(U15="","Sem anexo: tributação integral",INDEX('Referência LC 214'!$H$6:$H$967,U15))) | J15: =IF(T15="","",IF(U15="",0,INDEX('Referência LC 214'!$K$6:$K$967,U15))) | K15: =IF(OR(T15="",U15=""),"","Anexo "&INDEX('Referência LC 214'!$E$6:$E$967,U15)&", item "&INDEX('Referência LC 214'!$F$6:$F$967,U15)&": "&INDEX('Referência LC 214'!$G$6:$G$967,U15)) | L15: =IF(OR(T15="",U15=""),"",IF(INDEX('Referência LC 214'!$L$6:$L$967,U15)&""<>"",INDEX('Referência LC 214'!$L$6:$L$967,U15)&"",IF(SUMPRODUCT((LEFT(T15,LEN('Referência LC 214'!$N$6:$N$967))='Referência LC 214'!$N$6:$N$967)*('Referência LC 214'!$L$6:$L$967<>""))>0,"Há outro tratamento só para alguns compradores (ex.: órgão público/SUS) — veja a referência",""))) | M15: =IF(T15="","",IF(AND(C15<>"Serviço",LEN(T15)-1<>8),"NCM deve ter 8 dígitos",IF(AND(C15="Serviço",LEN(T15)-1<>9),"NBS deve ter 9 dígitos",IF(L15<>"","Benefício depende do comprador: confira a coluna N",IF(G15>1,"Mais de uma regra: confira o item do anexo na referência",IF(G15=0,"Sem redução na LC 214","Confira se o produto é o descrito no item")))))) | T15: =IF(D15="","",IF(C15="Serviço","S","P")&SUBSTITUTE(SUBSTITUTE(SUBSTITUTE(D15,".",""),"-","")," ","")) | U15: =IF(T15="","",IFERROR(MATCH(LEFT(T15,10),'Referência LC 214'!$N$6:$N$967,0),IFERROR(MATCH(LEFT(T15,9),'Referência LC 214'!$N$6:$N$967,0),IFERROR(MATCH(LEFT(T15,8),'Referência LC 214'!$N$6:$N$967,0),IFERROR(MATCH(LEFT(T15,7),'Referência LC 214'!$N$6:$N$967,0),IFERROR(MATCH(LEFT(T15,6),'Referência LC 214'!$N$6:$N$967,0),IFERROR(MATCH(LEFT(T15,5),'Referência LC 214'!$N$6:$N$967,0),IFERROR(MATCH(LEFT(T15,4),'Referência LC 214'!$N$6:$N$967,0),IFERROR(MATCH(LEFT(T15,3),'Referência LC 214'!$N$6:$N$967,0),"")))))))))
G16: =IF(T16="","",SUMPRODUCT(--(LEFT(T16,LEN('Referência LC 214'!$N$6:$N$967))='Referência LC 214'!$N$6:$N$967))) | H16: =IF(T16="","",IF(U16="","000001",INDEX('Referência LC 214'!$I$6:$I$967,U16))) | I16: =IF(T16="","",IF(U16="","Sem anexo: tributação integral",INDEX('Referência LC 214'!$H$6:$H$967,U16))) | J16: =IF(T16="","",IF(U16="",0,INDEX('Referência LC 214'!$K$6:$K$967,U16))) | K16: =IF(OR(T16="",U16=""),"","Anexo "&INDEX('Referência LC 214'!$E$6:$E$967,U16)&", item "&INDEX('Referência LC 214'!$F$6:$F$967,U16)&": "&INDEX('Referência LC 214'!$G$6:$G$967,U16)) | L16: =IF(OR(T16="",U16=""),"",IF(INDEX('Referência LC 214'!$L$6:$L$967,U16)&""<>"",INDEX('Referência LC 214'!$L$6:$L$967,U16)&"",IF(SUMPRODUCT((LEFT(T16,LEN('Referência LC 214'!$N$6:$N$967))='Referência LC 214'!$N$6:$N$967)*('Referência LC 214'!$L$6:$L$967<>""))>0,"Há outro tratamento só para alguns compradores (ex.: órgão público/SUS) — veja a referência",""))) | M16: =IF(T16="","",IF(AND(C16<>"Serviço",LEN(T16)-1<>8),"NCM deve ter 8 dígitos",IF(AND(C16="Serviço",LEN(T16)-1<>9),"NBS deve ter 9 dígitos",IF(L16<>"","Benefício depende do comprador: confira a coluna N",IF(G16>1,"Mais de uma regra: confira o item do anexo na referência",IF(G16=0,"Sem redução na LC 214","Confira se o produto é o descrito no item")))))) | T16: =IF(D16="","",IF(C16="Serviço","S","P")&SUBSTITUTE(SUBSTITUTE(SUBSTITUTE(D16,".",""),"-","")," ","")) | U16: =IF(T16="","",IFERROR(MATCH(LEFT(T16,10),'Referência LC 214'!$N$6:$N$967,0),IFERROR(MATCH(LEFT(T16,9),'Referência LC 214'!$N$6:$N$967,0),IFERROR(MATCH(LEFT(T16,8),'Referência LC 214'!$N$6:$N$967,0),IFERROR(MATCH(LEFT(T16,7),'Referência LC 214'!$N$6:$N$967,0),IFERROR(MATCH(LEFT(T16,6),'Referência LC 214'!$N$6:$N$967,0),IFERROR(MATCH(LEFT(T16,5),'Referência LC 214'!$N$6:$N$967,0),IFERROR(MATCH(LEFT(T16,4),'Referência LC 214'!$N$6:$N$967,0),IFERROR(MATCH(LEFT(T16,3),'Referência LC 214'!$N$6:$N$967,0),"")))))))))
G17: =IF(T17="","",SUMPRODUCT(--(LEFT(T17,LEN('Referência LC 214'!$N$6:$N$967))='Referência LC 214'!$N$6:$N$967))) | H17: =IF(T17="","",IF(U17="","000001",INDEX('Referência LC 214'!$I$6:$I$967,U17))) | I17: =IF(T17="","",IF(U17="","Sem anexo: tributação integral",INDEX('Referência LC 214'!$H$6:$H$967,U17))) | J17: =IF(T17="","",IF(U17="",0,INDEX('Referência LC 214'!$K$6:$K$967,U17))) | K17: =IF(OR(T17="",U17=""),"","Anexo "&INDEX('Referência LC 214'!$E$6:$E$967,U17)&", item "&INDEX('Referência LC 214'!$F$6:$F$967,U17)&": "&INDEX('Referência LC 214'!$G$6:$G$967,U17)) | L17: =IF(OR(T17="",U17=""),"",IF(INDEX('Referência LC 214'!$L$6:$L$967,U17)&""<>"",INDEX('Referência LC 214'!$L$6:$L$967,U17)&"",IF(SUMPRODUCT((LEFT(T17,LEN('Referência LC 214'!$N$6:$N$967))='Referência LC 214'!$N$6:$N$967)*('Referência LC 214'!$L$6:$L$967<>""))>0,"Há outro tratamento só para alguns compradores (ex.: órgão público/SUS) — veja a referência",""))) | M17: =IF(T17="","",IF(AND(C17<>"Serviço",LEN(T17)-1<>8),"NCM deve ter 8 dígitos",IF(AND(C17="Serviço",LEN(T17)-1<>9),"NBS deve ter 9 dígitos",IF(L17<>"","Benefício depende do comprador: confira a coluna N",IF(G17>1,"Mais de uma regra: confira o item do anexo na referência",IF(G17=0,"Sem redução na LC 214","Confira se o produto é o descrito no item")))))) | T17: =IF(D17="","",IF(C17="Serviço","S","P")&SUBSTITUTE(SUBSTITUTE(SUBSTITUTE(D17,".",""),"-","")," ","")) | U17: =IF(T17="","",IFERROR(MATCH(LEFT(T17,10),'Referência LC 214'!$N$6:$N$967,0),IFERROR(MATCH(LEFT(T17,9),'Referência LC 214'!$N$6:$N$967,0),IFERROR(MATCH(LEFT(T17,8),'Referência LC 214'!$N$6:$N$967,0),IFERROR(MATCH(LEFT(T17,7),'Referência LC 214'!$N$6:$N$967,0),IFERROR(MATCH(LEFT(T17,6),'Referência LC 214'!$N$6:$N$967,0),IFERROR(MATCH(LEFT(T17,5),'Referência LC 214'!$N$6:$N$967,0),IFERROR(MATCH(LEFT(T17,4),'Referência LC 214'!$N$6:$N$967,0),IFERROR(MATCH(LEFT(T17,3),'Referência LC 214'!$N$6:$N$967,0),"")))))))))
G18: =IF(T18="","",SUMPRODUCT(--(LEFT(T18,LEN('Referência LC 214'!$N$6:$N$967))='Referência LC 214'!$N$6:$N$967))) | H18: =IF(T18="","",IF(U18="","000001",INDEX('Referência LC 214'!$I$6:$I$967,U18))) | I18: =IF(T18="","",IF(U18="","Sem anexo: tributação integral",INDEX('Referência LC 214'!$H$6:$H$967,U18))) | J18: =IF(T18="","",IF(U18="",0,INDEX('Referência LC 214'!$K$6:$K$967,U18))) | K18: =IF(OR(T18="",U18=""),"","Anexo "&INDEX('Referência LC 214'!$E$6:$E$967,U18)&", item "&INDEX('Referência LC 214'!$F$6:$F$967,U18)&": "&INDEX('Referência LC 214'!$G$6:$G$967,U18)) | L18: =IF(OR(T18="",U18=""),"",IF(INDEX('Referência LC 214'!$L$6:$L$967,U18)&""<>"",INDEX('Referência LC 214'!$L$6:$L$967,U18)&"",IF(SUMPRODUCT((LEFT(T18,LEN('Referência LC 214'!$N$6:$N$967))='Referência LC 214'!$N$6:$N$967)*('Referência LC 214'!$L$6:$L$967<>""))>0,"Há outro tratamento só para alguns compradores (ex.: órgão público/SUS) — veja a referência",""))) | M18: =IF(T18="","",IF(AND(C18<>"Serviço",LEN(T18)-1<>8),"NCM deve ter 8 dígitos",IF(AND(C18="Serviço",LEN(T18)-1<>9),"NBS deve ter 9 dígitos",IF(L18<>"","Benefício depende do comprador: confira a coluna N",IF(G18>1,"Mais de uma regra: confira o item do anexo na referência",IF(G18=0,"Sem redução na LC 214","Confira se o produto é o descrito no item")))))) | T18: =IF(D18="","",IF(C18="Serviço","S","P")&SUBSTITUTE(SUBSTITUTE(SUBSTITUTE(D18,".",""),"-","")," ","")) | U18: =IF(T18="","",IFERROR(MATCH(LEFT(T18,10),'Referência LC 214'!$N$6:$N$967,0),IFERROR(MATCH(LEFT(T18,9),'Referência LC 214'!$N$6:$N$967,0),IFERROR(MATCH(LEFT(T18,8),'Referência LC 214'!$N$6:$N$967,0),IFERROR(MATCH(LEFT(T18,7),'Referência LC 214'!$N$6:$N$967,0),IFERROR(MATCH(LEFT(T18,6),'Referência LC 214'!$N$6:$N$967,0),IFERROR(MATCH(LEFT(T18,5),'Referência LC 214'!$N$6:$N$967,0),IFERROR(MATCH(LEFT(T18,4),'Referência LC 214'!$N$6:$N$967,0),IFERROR(MATCH(LEFT(T18,3),'Referência LC 214'!$N$6:$N$967,0),"")))))))))
G19: =IF(T19="","",SUMPRODUCT(--(LEFT(T19,LEN('Referência LC 214'!$N$6:$N$967))='Referência LC 214'!$N$6:$N$967))) | H19: =IF(T19="","",IF(U19="","000001",INDEX('Referência LC 214'!$I$6:$I$967,U19))) | I19: =IF(T19="","",IF(U19="","Sem anexo: tributação integral",INDEX('Referência LC 214'!$H$6:$H$967,U19))) | J19: =IF(T19="","",IF(U19="",0,INDEX('Referência LC 214'!$K$6:$K$967,U19))) | K19: =IF(OR(T19="",U19=""),"","Anexo "&INDEX('Referência LC 214'!$E$6:$E$967,U19)&", item "&INDEX('Referência LC 214'!$F$6:$F$967,U19)&": "&INDEX('Referência LC 214'!$G$6:$G$967,U19)) | L19: =IF(OR(T19="",U19=""),"",IF(INDEX('Referência LC 214'!$L$6:$L$967,U19)&""<>"",INDEX('Referência LC 214'!$L$6:$L$967,U19)&"",IF(SUMPRODUCT((LEFT(T19,LEN('Referência LC 214'!$N$6:$N$967))='Referência LC 214'!$N$6:$N$967)*('Referência LC 214'!$L$6:$L$967<>""))>0,"Há outro tratamento só para alguns compradores (ex.: órgão público/SUS) — veja a referência",""))) | M19: =IF(T19="","",IF(AND(C19<>"Serviço",LEN(T19)-1<>8),"NCM deve ter 8 dígitos",IF(AND(C19="Serviço",LEN(T19)-1<>9),"NBS deve ter 9 dígitos",IF(L19<>"","Benefício depende do comprador: confira a coluna N",IF(G19>1,"Mais de uma regra: confira o item do anexo na referência",IF(G19=0,"Sem redução na LC 214","Confira se o produto é o descrito no item")))))) | T19: =IF(D19="","",IF(C19="Serviço","S","P")&SUBSTITUTE(SUBSTITUTE(SUBSTITUTE(D19,".",""),"-","")," ","")) | U19: =IF(T19="","",IFERROR(MATCH(LEFT(T19,10),'Referência LC 214'!$N$6:$N$967,0),IFERROR(MATCH(LEFT(T19,9),'Referência LC 214'!$N$6:$N$967,0),IFERROR(MATCH(LEFT(T19,8),'Referência LC 214'!$N$6:$N$967,0),IFERROR(MATCH(LEFT(T19,7),'Referência LC 214'!$N$6:$N$967,0),IFERROR(MATCH(LEFT(T19,6),'Referência LC 214'!$N$6:$N$967,0),IFERROR(MATCH(LEFT(T19,5),'Referência LC 214'!$N$6:$N$967,0),IFERROR(MATCH(LEFT(T19,4),'Referência LC 214'!$N$6:$N$967,0),IFERROR(MATCH(LEFT(T19,3),'Referência LC 214'!$N$6:$N$967,0),"")))))))))
G20: =IF(T20="","",SUMPRODUCT(--(LEFT(T20,LEN('Referência LC 214'!$N$6:$N$967))='Referência LC 214'!$N$6:$N$967))) | H20: =IF(T20="","",IF(U20="","000001",INDEX('Referência LC 214'!$I$6:$I$967,U20))) | I20: =IF(T20="","",IF(U20="","Sem anexo: tributação integral",INDEX('Referência LC 214'!$H$6:$H$967,U20))) | J20: =IF(T20="","",IF(U20="",0,INDEX('Referência LC 214'!$K$6:$K$967,U20))) | K20: =IF(OR(T20="",U20=""),"","Anexo "&INDEX('Referência LC 214'!$E$6:$E$967,U20)&", item "&INDEX('Referência LC 214'!$F$6:$F$967,U20)&": "&INDEX('Referência LC 214'!$G$6:$G$967,U20)) | L20: =IF(OR(T20="",U20=""),"",IF(INDEX('Referência LC 214'!$L$6:$L$967,U20)&""<>"",INDEX('Referência LC 214'!$L$6:$L$967,U20)&"",IF(SUMPRODUCT((LEFT(T20,LEN('Referência LC 214'!$N$6:$N$967))='Referência LC 214'!$N$6:$N$967)*('Referência LC 214'!$L$6:$L$967<>""))>0,"Há outro tratamento só para alguns compradores (ex.: órgão público/SUS) — veja a referência",""))) | M20: =IF(T20="","",IF(AND(C20<>"Serviço",LEN(T20)-1<>8),"NCM deve ter 8 dígitos",IF(AND(C20="Serviço",LEN(T20)-1<>9),"NBS deve ter 9 dígitos",IF(L20<>"","Benefício depende do comprador: confira a coluna N",IF(G20>1,"Mais de uma regra: confira o item do anexo na referência",IF(G20=0,"Sem redução na LC 214","Confira se o produto é o descrito no item")))))) | T20: =IF(D20="","",IF(C20="Serviço","S","P")&SUBSTITUTE(SUBSTITUTE(SUBSTITUTE(D20,".",""),"-","")," ","")) | U20: =IF(T20="","",IFERROR(MATCH(LEFT(T20,10),'Referência LC 214'!$N$6:$N$967,0),IFERROR(MATCH(LEFT(T20,9),'Referência LC 214'!$N$6:$N$967,0),IFERROR(MATCH(LEFT(T20,8),'Referência LC 214'!$N$6:$N$967,0),IFERROR(MATCH(LEFT(T20,7),'Referência LC 214'!$N$6:$N$967,0),IFERROR(MATCH(LEFT(T20,6),'Referência LC 214'!$N$6:$N$967,0),IFERROR(MATCH(LEFT(T20,5),'Referência LC 214'!$N$6:$N$967,0),IFERROR(MATCH(LEFT(T20,4),'Referência LC 214'!$N$6:$N$967,0),IFERROR(MATCH(LEFT(T20,3),'Referência LC 214'!$N$6:$N$967,0),"")))))))))
G21: =IF(T21="","",SUMPRODUCT(--(LEFT(T21,LEN('Referência LC 214'!$N$6:$N$967))='Referência LC 214'!$N$6:$N$967))) | H21: =IF(T21="","",IF(U21="","000001",INDEX('Referência LC 214'!$I$6:$I$967,U21))) | I21: =IF(T21="","",IF(U21="","Sem anexo: tributação integral",INDEX('Referência LC 214'!$H$6:$H$967,U21))) | J21: =IF(T21="","",IF(U21="",0,INDEX('Referência LC 214'!$K$6:$K$967,U21))) | K21: =IF(OR(T21="",U21=""),"","Anexo "&INDEX('Referência LC 214'!$E$6:$E$967,U21)&", item "&INDEX('Referência LC 214'!$F$6:$F$967,U21)&": "&INDEX('Referência LC 214'!$G$6:$G$967,U21)) | L21: =IF(OR(T21="",U21=""),"",IF(INDEX('Referência LC 214'!$L$6:$L$967,U21)&""<>"",INDEX('Referência LC 214'!$L$6:$L$967,U21)&"",IF(SUMPRODUCT((LEFT(T21,LEN('Referência LC 214'!$N$6:$N$967))='Referência LC 214'!$N$6:$N$967)*('Referência LC 214'!$L$6:$L$967<>""))>0,"Há outro tratamento só para alguns compradores (ex.: órgão público/SUS) — veja a referência",""))) | M21: =IF(T21="","",IF(AND(C21<>"Serviço",LEN(T21)-1<>8),"NCM deve ter 8 dígitos",IF(AND(C21="Serviço",LEN(T21)-1<>9),"NBS deve ter 9 dígitos",IF(L21<>"","Benefício depende do comprador: confira a coluna N",IF(G21>1,"Mais de uma regra: confira o item do anexo na referência",IF(G21=0,"Sem redução na LC 214","Confira se o produto é o descrito no item")))))) | T21: =IF(D21="","",IF(C21="Serviço","S","P")&SUBSTITUTE(SUBSTITUTE(SUBSTITUTE(D21,".",""),"-","")," ","")) | U21: =IF(T21="","",IFERROR(MATCH(LEFT(T21,10),'Referência LC 214'!$N$6:$N$967,0),IFERROR(MATCH(LEFT(T21,9),'Referência LC 214'!$N$6:$N$967,0),IFERROR(MATCH(LEFT(T21,8),'Referência LC 214'!$N$6:$N$967,0),IFERROR(MATCH(LEFT(T21,7),'Referência LC 214'!$N$6:$N$967,0),IFERROR(MATCH(LEFT(T21,6),'Referência LC 214'!$N$6:$N$967,0),IFERROR(MATCH(LEFT(T21,5),'Referência LC 214'!$N$6:$N$967,0),IFERROR(MATCH(LEFT(T21,4),'Referência LC 214'!$N$6:$N$967,0),IFERROR(MATCH(LEFT(T21,3),'Referência LC 214'!$N$6:$N$967,0),"")))))))))
